Workbook

Sheet Sheet1
A1: Date | B1: Open | C1: High | D1: Low | E1: Close | F1: Adj Close | G1: Volume
A2: 44452 | B2: 1192 | C2: 1215 | D2: 1176.45 | E2: 1208.4 | F2: 982.33752 | G2: 3723138
A3: 44453 | B3: 1216 | C3: 1240.6 | D3: 1207 | E3: 1238.65 | F3: 1006.9285 | G3: 5593286
A4: 44454 | B4: 1238.65 | C4: 1288.95 | D4: 1230.25 | E4: 1273.25 | F4: 1035.0557 | G4: 6063895
A5: 44455 | B5: 1287.2 | C5: 1295.3 | D5: 1255.2 | E5: 1263.1 | F5: 1026.8042 | G5: 3616292
A6: 44456 | B6: 1265 | C6: 1281 | D6: 1258.5 | E6: 1263.3 | F6: 1026.9672 | G6: 4817180
A7: 44459 | B7: 1258 | C7: 1298.8 | D7: 1250 | E7: 1276.15 | F7: 1037.4132 | G7: 5453683
A8: 44460 | B8: 1289 | C8: 1315 | D8: 1277 | E8: 1299.5 | F8: 1056.3949 | G8: 4645597
A9: 44461 | B9: 1300 | C9: 1328.65 | D9: 1299.6 | E9: 1315.5 | F9: 1069.4016 | G9: 5367303
A10: 44462 | B10: 1326.85 | C10: 1336.45 | D10: 1313.9 | E10: 1328.3 | F10: 1079.8071 | G10: 3037295
A11: 44463 | B11: 1340 | C11: 1377.75 | D11: 1337 | E11: 1358.2 | F11: 1104.1132 | G11: 7951730
A12: 44466 | B12: 1366 | C12: 1367.95 | D12: 1290.05 | E12: 1295.2 | F12: 1052.899 | G12: 7653504
A13: 44467 | B13: 1304.95 | C13: 1304.95 | D13: 1254 | E13: 1269 | F13: 1031.6008 | G13: 8572321
... A1242: 46276 | B1242: 1196 | C1242: 1223.4 | D1242: 1195.7 | E1242: 1206.1 | F1242: 1206.1 | G1242: 2272618

Sheet Mean Rev
B3: Wipro Ltd | F3: Nifty50 Return
B4: Date | C4: Close Price | D4: Return | F4: Date | G4: Close Price | H4: Return
B5: 44452 | C5: =IFERROR(INDEX(Sheet1!F2:F1242,MATCH('Mean Rev'!B5,Sheet1!A2:A1242,0)),0) -> 982.33752 | F5: =B5 -> 44452 | G5: =IFERROR(INDEX([1]Sheet1!$F$2:$F$1238,MATCH('Mean Rev'!F5,[1]Sheet1!$A$2:$A$1238,0)),0) -> 17355.301
B6: 44453 | C6: =IFERROR(INDEX(Sheet1!F3:F1243,MATCH('Mean Rev'!B6,Sheet1!A3:A1243,0)),0) -> 1006.9285 | D6: =LN(C6/C5) -> 0.024724894 | F6: =B6 -> 44453 | G6: =IFERROR(INDEX([1]Sheet1!$F$2:$F$1238,MATCH('Mean Rev'!F6,[1]Sheet1!$A$2:$A$1238,0)),0) -> 17380 | H6: =LN(G6/G5) -> 0.0014221396
B7: 44454 | C7: =IFERROR(INDEX(Sheet1!F4:F1244,MATCH('Mean Rev'!B7,Sheet1!A4:A1244,0)),0) -> 1035.0557 | D7: =LN(C7/C6) -> 0.027550632 | F7: =B7 -> 44454 | G7: =IFERROR(INDEX([1]Sheet1!$F$2:$F$1238,MATCH('Mean Rev'!F7,[1]Sheet1!$A$2:$A$1238,0)),0) -> 17519.449 | H7: =LN(G7/G6) -> 0.0079915279
B8: 44455 | C8: =IFERROR(INDEX(Sheet1!F5:F1245,MATCH('Mean Rev'!B8,Sheet1!A5:A1245,0)),0) -> 1026.8042 | D8: =LN(C8/C7) -> -0.0080039474 | F8: =B8 -> 44455 | G8: =IFERROR(INDEX([1]Sheet1!$F$2:$F$1238,MATCH('Mean Rev'!F8,[1]Sheet1!$A$2:$A$1238,0)),0) -> 17629.5 | H8: =LN(G8/G7) -> 0.0062619875 | O8: SUMMARY OUTPUT
B9: 44456 | C9: =IFERROR(INDEX(Sheet1!F6:F1246,MATCH('Mean Rev'!B9,Sheet1!A6:A1246,0)),0) -> 1026.9672 | D9: =LN(C9/C8) -> 0.00015869719 | F9: =B9 -> 44456 | G9: =IFERROR(INDEX([1]Sheet1!$F$2:$F$1238,MATCH('Mean Rev'!F9,[1]Sheet1!$A$2:$A$1238,0)),0) -> 17585.15 | H9: =LN(G9/G8) -> -0.0025188172 | J9: Beta Drafting
B10: 44459 | C10: =IFERROR(INDEX(Sheet1!F7:F1247,MATCH('Mean Rev'!B10,Sheet1!A7:A1247,0)),0) -> 1037.4132 | D10: =LN(C10/C9) -> 0.010120358 | F10: =B10 -> 44459 | G10: =IFERROR(INDEX([1]Sheet1!$F$2:$F$1238,MATCH('Mean Rev'!F10,[1]Sheet1!$A$2:$A$1238,0)),0) -> 17396.9 | H10: =LN(G10/G9) -> -0.010762766 | O10: Regression Statistics
B11: 44460 | C11: =IFERROR(INDEX(Sheet1!F8:F1248,MATCH('Mean Rev'!B11,Sheet1!A8:A1248,0)),0) -> 1056.3949 | D11: =LN(C11/C10) -> 0.018131757 | F11: =B11 -> 44460 | G11: =IFERROR(INDEX([1]Sheet1!$F$2:$F$1238,MATCH('Mean Rev'!F11,[1]Sheet1!$A$2:$A$1238,0)),0) -> 17562 | H11: =LN(G11/G10) -> 0.0094454251 | O11: Multiple R | P11: 0.48528291
B12: 44461 | C12: =IFERROR(INDEX(Sheet1!F9:F1249,MATCH('Mean Rev'!B12,Sheet1!A9:A1249,0)),0) -> 1069.4016 | D12: =LN(C12/C11) -> 0.012237179 | F12: =B12 -> 44461 | G12: =IFERROR(INDEX([1]Sheet1!$F$2:$F$1238,MATCH('Mean Rev'!F12,[1]Sheet1!$A$2:$A$1238,0)),0) -> 17546.65 | H12: =LN(G12/G11) -> -0.00087440618 | J12: Levered Raw Beta | K12: =P25 -> 0.88670867 | O12: R Square | P12: 0.23549951
B13: 44462 | C13: =IFERROR(INDEX(Sheet1!F10:F1250,MATCH('Mean Rev'!B13,Sheet1!A10:A1250,0)),0) -> 1079.8071 | D13: =LN(C13/C12) -> 0.0096831906 | F13: =B13 -> 44462 | G13: =IFERROR(INDEX([1]Sheet1!$F$2:$F$1238,MATCH('Mean Rev'!F13,[1]Sheet1!$A$2:$A$1238,0)),0) -> 17822.949 | H13: =LN(G13/G12) -> 0.015623838 | J13: Raw Beta Weight | K13: 0.65 | O13: Adjusted R Square | P13: 0.23487998
B14: 44463 | C14: =IFERROR(INDEX(Sheet1!F11:F1251,MATCH('Mean Rev'!B14,Sheet1!A11:A1251,0)),0) -> 1104.1132 | D14: =LN(C14/C13) -> 0.022260001 | F14: =B14 -> 44463 | G14: =IFERROR(INDEX([1]Sheet1!$F$2:$F$1238,MATCH('Mean Rev'!F14,[1]Sheet1!$A$2:$A$1238,0)),0) -> 17853.199 | H14: =LN(G14/G13) -> 0.0016958113 | O14: Standard Error | P14: 0.013923017
B15: 44466 | C15: =IFERROR(INDEX(Sheet1!F12:F1252,MATCH('Mean Rev'!B15,Sheet1!A12:A1252,0)),0) -> 1052.899 | D15: =LN(C15/C14) -> -0.047495084 | F15: =B15 -> 44466 | G15: =IFERROR(INDEX([1]Sheet1!$F$2:$F$1238,MATCH('Mean Rev'!F15,[1]Sheet1!$A$2:$A$1238,0)),0) -> 17855.1 | H15: =LN(G15/G14) -> 0.00010643972 | J15: Market Beta | K15: 1 | O15: Observations | P15: 1236
B16: 44467 | C16: =IFERROR(INDEX(Sheet1!F13:F1253,MATCH('Mean Rev'!B16,Sheet1!A13:A1253,0)),0) -> 1031.6008 | D16: =LN(C16/C15) -> -0.020435558 | F16: =B16 -> 44467 | G16: =IFERROR(INDEX([1]Sheet1!$F$2:$F$1238,MATCH('Mean Rev'!F16,[1]Sheet1!$A$2:$A$1238,0)),0) -> 17748.6 | H16: =LN(G16/G15) -> -0.0059825423 | J16: Market Beta Weight | K16: 0.35
B17: 44468 | C17: =IFERROR(INDEX(Sheet1!F14:F1254,MATCH('Mean Rev'!B17,Sheet1!A14:A1254,0)),0) -> 1041.5184 | D17: =LN(C17/C16) -> 0.00956788 | F17: =B17 -> 44468 | G17: =IFERROR(INDEX([1]Sheet1!$F$2:$F$1238,MATCH('Mean Rev'!F17,[1]Sheet1!$A$2:$A$1238,0)),0) -> 17711.301 | H17: =LN(G17/G16) -> -0.0021037195 | O17: ANOVA
B18: 44469 | C18: =IFERROR(INDEX(Sheet1!F15:F1255,MATCH('Mean Rev'!B18,Sheet1!A15:A1255,0)),0) -> 1040.1772 | D18: =LN(C18/C17) -> -0.0012885521 | F18: =B18 -> 44469 | G18: =IFERROR(INDEX([1]Sheet1!$F$2:$F$1238,MATCH('Mean Rev'!F18,[1]Sheet1!$A$2:$A$1238,0)),0) -> 17618.15 | H18: =LN(G18/G17) -> -0.0052732552 | J18: Adjusted Beta | K18: =(K12*K13)+(K15*K16) -> 0.92636064 | P18: df | Q18: SS | R18: MS | S18: F | T18: Significance F
B19: 44470 | C19: =IFERROR(INDEX(Sheet1!F16:F1256,MATCH('Mean Rev'!B19,Sheet1!A16:A1256,0)),0) -> 1035.4622 | D19: =LN(C19/C18) -> -0.0045432709 | F19: =B19 -> 44470 | G19: =IFERROR(INDEX([1]Sheet1!$F$2:$F$1238,MATCH('Mean Rev'!F19,[1]Sheet1!$A$2:$A$1238,0)),0) -> 17532.051 | H19: =LN(G19/G18) -> -0.0048989638 | O19: Regression | P19: 1 | Q19: 0.07368755 | R19: 0.07368755 | S19: 380.12584 | T19: 5.1659483e-74
B20: 44473 | C20: =IFERROR(INDEX(Sheet1!F17:F1257,MATCH('Mean Rev'!B20,Sheet1!A17:A1257,0)),0) -> 1039.4454 | D20: =LN(C20/C19) -> 0.0038394782 | F20: =B20 -> 44473 | G20: =IFERROR(INDEX([1]Sheet1!$F$2:$F$1238,MATCH('Mean Rev'!F20,[1]Sheet1!$A$2:$A$1238,0)),0) -> 17691.25 | H20: =LN(G20/G19) -> 0.009039488 | O20: Residual | P20: 1234 | Q20: 0.23921141 | R20: 0.00019385041
B21: 44474 | C21: =IFERROR(INDEX(Sheet1!F18:F1258,MATCH('Mean Rev'!B21,Sheet1!A18:A1258,0)),0) -> 1060.9879 | D21: =LN(C21/C20) -> 0.020513134 | F21: =B21 -> 44474 | G21: =IFERROR(INDEX([1]Sheet1!$F$2:$F$1238,MATCH('Mean Rev'!F21,[1]Sheet1!$A$2:$A$1238,0)),0) -> 17822.301 | H21: =LN(G21/G20) -> 0.0073803589 | O21: Total | P21: 1235 | Q21: 0.31289896
B22: 44475 | C22: =IFERROR(INDEX(Sheet1!F19:F1259,MATCH('Mean Rev'!B22,Sheet1!A19:A1259,0)),0) -> 1036.8441 | D22: =LN(C22/C21) -> -0.023018873 | F22: =B22 -> 44475 | G22: =IFERROR(INDEX([1]Sheet1!$F$2:$F$1238,MATCH('Mean Rev'!F22,[1]Sheet1!$A$2:$A$1238,0)),0) -> 17646 | H22: =LN(G22/G21) -> -0.0099413972
B23: 44476 | C23: =IFERROR(INDEX(Sheet1!F20:F1260,MATCH('Mean Rev'!B23,Sheet1!A20:A1260,0)),0) -> 1061.923 | D23: =LN(C23/C22) -> 0.023899795 | F23: =B23 -> 44476 | G23: =IFERROR(INDEX([1]Sheet1!$F$2:$F$1238,MATCH('Mean Rev'!F23,[1]Sheet1!$A$2:$A$1238,0)),0) -> 17790.35 | H23: =LN(G23/G22) -> 0.0081470247 | P23: Coefficients | Q23: Standard Error | R23: t Stat | S23: P-value | T23: Lower 95% | U23: Upper 95% | V23: Lower 95.0% | W23: Upper 95.0%
B24: 44477 | C24: =IFERROR(INDEX(Sheet1!F21:F1261,MATCH('Mean Rev'!B24,Sheet1!A21:A1261,0)),0) -> 1074.8075 | D24: =LN(C24/C23) -> 0.012060181 | F24: =B24 -> 44477 | G24: =IFERROR(INDEX([1]Sheet1!$F$2:$F$1238,MATCH('Mean Rev'!F24,[1]Sheet1!$A$2:$A$1238,0)),0) -> 17895.199 | H24: =LN(G24/G23) -> 0.0058763233 | O24: Intercept | P24: -4.8299318e-05 | Q24: 0.00039617894 | R24: -0.12191289 | S24: 0.90298786 | T24: -0.00082555812 | U24: 0.00072895949 | V24: -0.00082555812 | W24: 0.00072895949
B25: 44480 | C25: =IFERROR(INDEX(Sheet1!F22:F1262,MATCH('Mean Rev'!B25,Sheet1!A22:A1262,0)),0) -> 1059.1591 | D25: =LN(C25/C24) -> -0.01466632 | F25: =B25 -> 44480 | G25: =IFERROR(INDEX([1]Sheet1!$F$2:$F$1238,MATCH('Mean Rev'!F25,[1]Sheet1!$A$2:$A$1238,0)),0) -> 17945.949 | H25: =LN(G25/G24) -> 0.0028319424 | O25: X Variable 1 | P25: 0.88670867 | Q25: 0.045479665 | R25: 19.496816 | S25: 5.1659483e-74 | T25: 0.79748265 | U25: 0.97593469 | V25: 0.79748265 | W25: 0.97593469
B26: 44481 | C26: =IFERROR(INDEX(Sheet1!F23:F1263,MATCH('Mean Rev'!B26,Sheet1!A23:A1263,0)),0) -> 1016.4398 | D26: =LN(C26/C25) -> -0.041169103 | F26: =B26 -> 44481 | G26: =IFERROR(INDEX([1]Sheet1!$F$2:$F$1238,MATCH('Mean Rev'!F26,[1]Sheet1!$A$2:$A$1238,0)),0) -> 17991.949 | H26: =LN(G26/G25) -> 0.002559973
B27: 44482 | C27: =IFERROR(INDEX(Sheet1!F24:F1264,MATCH('Mean Rev'!B27,Sheet1!A24:A1264,0)),0) -> 1028.6335 | D27: =LN(C27/C26) -> 0.011925118 | F27: =B27 -> 44482 | G27: =IFERROR(INDEX([1]Sheet1!$F$2:$F$1238,MATCH('Mean Rev'!F27,[1]Sheet1!$A$2:$A$1238,0)),0) -> 18161.75 | H27: =LN(G27/G26) -> 0.009393342
B28: 44483 | C28: =IFERROR(INDEX(Sheet1!F25:F1265,MATCH('Mean Rev'!B28,Sheet1!A25:A1265,0)),0) -> 1017.0903 | D28: =LN(C28/C27) -> -0.011285391 | F28: =B28 -> 44483 | G28: =IFERROR(INDEX([1]Sheet1!$F$2:$F$1238,MATCH('Mean Rev'!F28,[1]Sheet1!$A$2:$A$1238,0)),0) -> 18338.551 | H28: =LN(G28/G27) -> 0.00968771
B29: 44487 | C29: =IFERROR(INDEX(Sheet1!F26:F1266,MATCH('Mean Rev'!B29,Sheet1!A26:A1266,0)),0) -> 992.90552 | D29: =LN(C29/C28) -> -0.024065643 | F29: =B29 -> 44487 | G29: =IFERROR(INDEX([1]Sheet1!$F$2:$F$1238,MATCH('Mean Rev'!F29,[1]Sheet1!$A$2:$A$1238,0)),0) -> 18477.051 | H29: =LN(G29/G28) -> 0.0075240196 | O29: RESIDUAL OUTPUT
B30: 44488 | C30: =IFERROR(INDEX(Sheet1!F27:F1267,MATCH('Mean Rev'!B30,Sheet1!A27:A1267,0)),0) -> 1001.6038 | D30: =LN(C30/C29) -> 0.008722243 | F30: =B30 -> 44488 | G30: =IFERROR(INDEX([1]Sheet1!$F$2:$F$1238,MATCH('Mean Rev'!F30,[1]Sheet1!$A$2:$A$1238,0)),0) -> 18418.75 | H30: =LN(G30/G29) -> -0.0031602962
B31: 44489 | C31: =IFERROR(INDEX(Sheet1!F28:F1268,MATCH('Mean Rev'!B31,Sheet1!A28:A1268,0)),0) -> 1002.2542 | D31: =LN(C31/C30) -> 0.00064919939 | F31: =B31 -> 44489 | G31: =IFERROR(INDEX([1]Sheet1!$F$2:$F$1238,MATCH('Mean Rev'!F31,[1]Sheet1!$A$2:$A$1238,0)),0) -> 18266.6 | H31: =LN(G31/G30) -> -0.0082949332 | O31: Observation | P31: Predicted Y | Q31: Residuals
B32: 44490 | C32: =IFERROR(INDEX(Sheet1!F29:F1269,MATCH('Mean Rev'!B32,Sheet1!A29:A1269,0)),0) -> 992.25543 | D32: =LN(C32/C31) -> -0.010026387 | F32: =B32 -> 44490 | G32: =IFERROR(INDEX([1]Sheet1!$F$2:$F$1238,MATCH('Mean Rev'!F32,[1]Sheet1!$A$2:$A$1238,0)),0) -> 18178.1 | H32: =LN(G32/G31) -> -0.0048566829 | O32: 1 | P32: 0.0012127242 | Q32: 0.02351217
B33: 44491 | C33: =IFERROR(INDEX(Sheet1!F30:F1270,MATCH('Mean Rev'!B33,Sheet1!A30:A1270,0)),0) -> 978.56842 | D33: =LN(C33/C32) -> -0.013889858 | F33: =B33 -> 44491 | G33: =IFERROR(INDEX([1]Sheet1!$F$2:$F$1238,MATCH('Mean Rev'!F33,[1]Sheet1!$A$2:$A$1238,0)),0) -> 18114.9 | H33: =LN(G33/G32) -> -0.0034827257 | O33: 2 | P33: 0.0070378578 | Q33: 0.020512774
B34: 44494 | C34: =IFERROR(INDEX(Sheet1!F31:F1271,MATCH('Mean Rev'!B34,Sheet1!A31:A1271,0)),0) -> 955.12891 | D34: =LN(C34/C33) -> -0.024244396 | F34: =B34 -> 44494 | G34: =IFERROR(INDEX([1]Sheet1!$F$2:$F$1238,MATCH('Mean Rev'!F34,[1]Sheet1!$A$2:$A$1238,0)),0) -> 18125.4 | H34: =LN(G34/G33) -> 0.00057946541 | O34: 3 | P34: 0.0055042593 | Q34: -0.013508207
B35: 44495 | C35: =IFERROR(INDEX(Sheet1!F32:F1272,MATCH('Mean Rev'!B35,Sheet1!A32:A1272,0)),0) -> 956.27618 | D35: =LN(C35/C34) -> 0.0012004551 | F35: =B35 -> 44495 | G35: =IFERROR(INDEX([1]Sheet1!$F$2:$F$1238,MATCH('Mean Rev'!F35,[1]Sheet1!$A$2:$A$1238,0)),0) -> 18268.4 | H35: =LN(G35/G34) -> 0.0078585217 | O35: 4 | P35: -0.0022817563 | Q35: 0.0024404535
B36: 44496 | C36: =IFERROR(INDEX(Sheet1!F33:F1273,MATCH('Mean Rev'!B36,Sheet1!A33:A1273,0)),0) -> 964.75848 | D36: =LN(C36/C35) -> 0.0088310274 | F36: =B36 -> 44496 | G36: =IFERROR(INDEX([1]Sheet1!$F$2:$F$1238,MATCH('Mean Rev'!F36,[1]Sheet1!$A$2:$A$1238,0)),0) -> 18210.949 | H36: =LN(G36/G35) -> -0.0031497941 | O36: 5 | P36: -0.0095917375 | Q36: 0.019712095
B37: 44497 | C37: =IFERROR(INDEX(Sheet1!F34:F1274,MATCH('Mean Rev'!B37,Sheet1!A34:A1274,0)),0) -> 944.14624 | D37: =LN(C37/C36) -> -0.021596725 | F37: =B37 -> 44497 | G37: =IFERROR(INDEX([1]Sheet1!$F$2:$F$1238,MATCH('Mean Rev'!F37,[1]Sheet1!$A$2:$A$1238,0)),0) -> 17857.25 | H37: =LN(G37/G36) -> -0.01961343 | O37: 6 | P37: 0.008327041 | Q37: 0.0098047156
B38: 44498 | C38: =IFERROR(INDEX(Sheet1!F35:F1275,MATCH('Mean Rev'!B38,Sheet1!A35:A1275,0)),0) -> 937.38507 | D38: =LN(C38/C37) -> -0.0071869105 | F38: =B38 -> 44498 | G38: =IFERROR(INDEX([1]Sheet1!$F$2:$F$1238,MATCH('Mean Rev'!F38,[1]Sheet1!$A$2:$A$1238,0)),0) -> 17671.65 | H38: =LN(G38/G37) -> -0.010447906 | O38: 7 | P38: -0.00082364286 | Q38: 0.013060822
B39: 44501 | C39: =IFERROR(INDEX(Sheet1!F36:F1276,MATCH('Mean Rev'!B39,Sheet1!A36:A1276,0)),0) -> 974.63446 | D39: =LN(C39/C38) -> 0.038968329 | F39: =B39 -> 44501 | G39: =IFERROR(INDEX([1]Sheet1!$F$2:$F$1238,MATCH('Mean Rev'!F39,[1]Sheet1!$A$2:$A$1238,0)),0) -> 17929.65 | H39: =LN(G39/G38) -> 0.014494106 | O39: 8 | P39: 0.013805493 | Q39: -0.0041223029
B40: 44502 | C40: =IFERROR(INDEX(Sheet1!F37:F1277,MATCH('Mean Rev'!B40,Sheet1!A37:A1277,0)),0) -> 959.43158 | D40: =LN(C40/C39) -> -0.015721484 | F40: =B40 -> 44502 | G40: =IFERROR(INDEX([1]Sheet1!$F$2:$F$1238,MATCH('Mean Rev'!F40,[1]Sheet1!$A$2:$A$1238,0)),0) -> 17888.949 | H40: =LN(G40/G39) -> -0.0022726287 | O40: 9 | P40: 0.0014553912 | Q40: 0.02080461
B41: 44503 | C41: =IFERROR(INDEX(Sheet1!F38:F1278,MATCH('Mean Rev'!B41,Sheet1!A38:A1278,0)),0) -> 964.10309 | D41: =LN(C41/C40) -> 0.0048572225 | F41: =B41 -> 44503 | G41: =IFERROR(INDEX([1]Sheet1!$F$2:$F$1238,MATCH('Mean Rev'!F41,[1]Sheet1!$A$2:$A$1238,0)),0) -> 17829.199 | H41: =LN(G41/G40) -> -0.0033456413 | O41: 10 | P41: 4.6081703e-05 | Q41: -0.047541166
B42: 44504 | C42: =IFERROR(INDEX(Sheet1!F39:F1279,MATCH('Mean Rev'!B42,Sheet1!A39:A1279,0)),0) -> 969.63513 | D42: =LN(C42/C41) -> 0.0057216209 | F42: =B42 -> 44504 | G42: =IFERROR(INDEX([1]Sheet1!$F$2:$F$1238,MATCH('Mean Rev'!F42,[1]Sheet1!$A$2:$A$1238,0)),0) -> 17916.801 | H42: =LN(G42/G41) -> 0.0049013449 | O42: 11 | P42: -0.0053530714 | Q42: -0.015082486
...
