Workbook

Sheet Sheet1
A1: Date | B1: Open | C1: High | D1: Low | E1: Close | F1: Adj Close | G1: Volume
A2: 44452 | B2: 1683 | C2: 1701.5 | D2: 1675.2 | E2: 1691.9 | F2: 1473.5985 | G2: 4662374
A3: 44453 | B3: 1695.95 | C3: 1695.95 | D3: 1678.6 | E3: 1686.15 | F3: 1468.5902 | G3: 4945167
A4: 44454 | B4: 1693.25 | C4: 1715.1 | D4: 1690.2 | E4: 1711.45 | F4: 1490.6259 | G4: 4062344
A5: 44455 | B5: 1715.2 | C5: 1719.25 | D5: 1691.45 | E5: 1702.25 | F5: 1482.613 | G5: 3246568
A6: 44456 | B6: 1697 | C6: 1718 | D6: 1684.45 | E6: 1691.3 | F6: 1473.0758 | G6: 7454864
A7: 44459 | B7: 1685 | C7: 1707.7 | D7: 1677.95 | E7: 1687.85 | F7: 1470.0709 | G7: 5660743
A8: 44460 | B8: 1700 | C8: 1726.75 | D8: 1684.65 | E8: 1718.45 | F8: 1496.7227 | G8: 4672222
A9: 44461 | B9: 1717 | C9: 1738.9 | D9: 1713.05 | E9: 1716.9 | F9: 1495.3727 | G9: 4553892
A10: 44462 | B10: 1732 | C10: 1745 | D10: 1721.1 | E10: 1742.55 | F10: 1517.7131 | G10: 3826090
A11: 44463 | B11: 1758 | C11: 1788 | D11: 1752.45 | E11: 1763.85 | F11: 1536.2648 | G11: 8280446
A12: 44466 | B12: 1768.75 | C12: 1769 | D12: 1718.1 | E12: 1721.15 | F12: 1499.0742 | G12: 5045337
A13: 44467 | B13: 1710 | C13: 1710 | D13: 1675 | E13: 1687.1 | F13: 1469.4178 | G13: 6557197
... A1242: 46276 | B1242: 1032 | C1242: 1047.3 | D1242: 1029.7 | E1242: 1037.7 | F1242: 1037.7 | G1242: 6164796

Sheet Sheet2

Sheet Mean_Rev
B2: Regression Beta - 5 Daily Monthly
B3: Wipro Ltd | F3: Nifty50 Return
B5: Date | C5: Close Price | D5: Return | F5: Date | G5: Close Price | H5: Return
B6: 44452 | C6: =IFERROR(INDEX(Sheet1!F2:F1242,MATCH(Mean_Rev!B6,Sheet1!A2:A1242,0)),0) -> 1473.5985 | F6: =B6 -> 44452 | G6: =IFERROR(INDEX([1]Sheet1!$F$2:$F$1238,MATCH(F6,[1]Sheet1!$A$2:$A$1238,0)),0) -> 17355.301
B7: 44453 | C7: =IFERROR(INDEX(Sheet1!F3:F1243,MATCH(Mean_Rev!B7,Sheet1!A3:A1243,0)),0) -> 1468.5902 | D7: =LN(C7/C6) -> -0.0034044761 | F7: =B7 -> 44453 | G7: =IFERROR(INDEX([1]Sheet1!$F$2:$F$1238,MATCH(F7,[1]Sheet1!$A$2:$A$1238,0)),0) -> 17380 | H7: =LN(G7/G6) -> 0.0014221396 | J7: Beta Drafting | N7: SUMMARY OUTPUT
B8: 44454 | C8: =IFERROR(INDEX(Sheet1!F4:F1244,MATCH(Mean_Rev!B8,Sheet1!A4:A1244,0)),0) -> 1490.6259 | D8: =LN(C8/C7) -> 0.014893169 | F8: =B8 -> 44454 | G8: =IFERROR(INDEX([1]Sheet1!$F$2:$F$1238,MATCH(F8,[1]Sheet1!$A$2:$A$1238,0)),0) -> 17519.449 | H8: =LN(G8/G7) -> 0.0079915279
B9: 44455 | C9: =IFERROR(INDEX(Sheet1!F5:F1245,MATCH(Mean_Rev!B9,Sheet1!A5:A1245,0)),0) -> 1482.613 | D9: =LN(C9/C8) -> -0.0053899717 | F9: =B9 -> 44455 | G9: =IFERROR(INDEX([1]Sheet1!$F$2:$F$1238,MATCH(F9,[1]Sheet1!$A$2:$A$1238,0)),0) -> 17629.5 | H9: =LN(G9/G8) -> 0.0062619875 | N9: Regression Statistics
B10: 44456 | C10: =IFERROR(INDEX(Sheet1!F6:F1246,MATCH(Mean_Rev!B10,Sheet1!A6:A1246,0)),0) -> 1473.0758 | D10: =LN(C10/C9) -> -0.006453497 | F10: =B10 -> 44456 | G10: =IFERROR(INDEX([1]Sheet1!$F$2:$F$1238,MATCH(F10,[1]Sheet1!$A$2:$A$1238,0)),0) -> 17585.15 | H10: =LN(G10/G9) -> -0.0025188172 | J10: Levered Raw Beta | K10: =O24 -> 0.98178528 | N10: Multiple R | O10: 0.52112907
B11: 44459 | C11: =IFERROR(INDEX(Sheet1!F7:F1247,MATCH(Mean_Rev!B11,Sheet1!A7:A1247,0)),0) -> 1470.0709 | D11: =LN(C11/C10) -> -0.0020419531 | F11: =B11 -> 44459 | G11: =IFERROR(INDEX([1]Sheet1!$F$2:$F$1238,MATCH(F11,[1]Sheet1!$A$2:$A$1238,0)),0) -> 17396.9 | H11: =LN(G11/G10) -> -0.010762766 | J11: Raw Beta Weight | K11: 0.65 | N11: R Square | O11: 0.27157551
B12: 44460 | C12: =IFERROR(INDEX(Sheet1!F8:F1248,MATCH(Mean_Rev!B12,Sheet1!A8:A1248,0)),0) -> 1496.7227 | D12: =LN(C12/C11) -> 0.017967175 | F12: =B12 -> 44460 | G12: =IFERROR(INDEX([1]Sheet1!$F$2:$F$1238,MATCH(F12,[1]Sheet1!$A$2:$A$1238,0)),0) -> 17562 | H12: =LN(G12/G11) -> 0.0094454251 | N12: Adjusted R Square | O12: 0.27098522
B13: 44461 | C13: =IFERROR(INDEX(Sheet1!F9:F1249,MATCH(Mean_Rev!B13,Sheet1!A9:A1249,0)),0) -> 1495.3727 | D13: =LN(C13/C12) -> -0.00090236141 | F13: =B13 -> 44461 | G13: =IFERROR(INDEX([1]Sheet1!$F$2:$F$1238,MATCH(F13,[1]Sheet1!$A$2:$A$1238,0)),0) -> 17546.65 | H13: =LN(G13/G12) -> -0.00087440618 | J13: Market Beta | K13: 1 | N13: Standard Error | O13: 0.014012706
B14: 44462 | C14: =IFERROR(INDEX(Sheet1!F10:F1250,MATCH(Mean_Rev!B14,Sheet1!A10:A1250,0)),0) -> 1517.7131 | D14: =LN(C14/C13) -> 0.014829225 | F14: =B14 -> 44462 | G14: =IFERROR(INDEX([1]Sheet1!$F$2:$F$1238,MATCH(F14,[1]Sheet1!$A$2:$A$1238,0)),0) -> 17822.949 | H14: =LN(G14/G13) -> 0.015623838 | J14: Market Beta Weight | K14: 0.35 | N14: Observations | O14: 1236
B15: 44463 | C15: =IFERROR(INDEX(Sheet1!F11:F1251,MATCH(Mean_Rev!B15,Sheet1!A11:A1251,0)),0) -> 1536.2648 | D15: =LN(C15/C14) -> 0.012149311 | F15: =B15 -> 44463 | G15: =IFERROR(INDEX([1]Sheet1!$F$2:$F$1238,MATCH(F15,[1]Sheet1!$A$2:$A$1238,0)),0) -> 17853.199 | H15: =LN(G15/G14) -> 0.0016958113
B16: 44466 | C16: =IFERROR(INDEX(Sheet1!F12:F1252,MATCH(Mean_Rev!B16,Sheet1!A12:A1252,0)),0) -> 1499.0742 | D16: =LN(C16/C15) -> -0.024506266 | F16: =B16 -> 44466 | G16: =IFERROR(INDEX([1]Sheet1!$F$2:$F$1238,MATCH(F16,[1]Sheet1!$A$2:$A$1238,0)),0) -> 17855.1 | H16: =LN(G16/G15) -> 0.00010643972 | J16: Adjusted Beta | K16: =(K10*K11)+(K13*K14) -> 0.98816043 | N16: ANOVA
B17: 44467 | C17: =IFERROR(INDEX(Sheet1!F13:F1253,MATCH(Mean_Rev!B17,Sheet1!A13:A1253,0)),0) -> 1469.4178 | D17: =LN(C17/C16) -> -0.01998143 | F17: =B17 -> 44467 | G17: =IFERROR(INDEX([1]Sheet1!$F$2:$F$1238,MATCH(F17,[1]Sheet1!$A$2:$A$1238,0)),0) -> 17748.6 | H17: =LN(G17/G16) -> -0.0059825423 | K17: =SLOPE(D6:D1242,H6:H1242) -> 0.98178528 | O17: df | P17: SS | Q17: MS | R17: F | S17: Significance F
B18: 44468 | C18: =IFERROR(INDEX(Sheet1!F14:F1254,MATCH(Mean_Rev!B18,Sheet1!A14:A1254,0)),0) -> 1473.9033 | D18: =LN(C18/C17) -> 0.0030479019 | F18: =B18 -> 44468 | G18: =IFERROR(INDEX([1]Sheet1!$F$2:$F$1238,MATCH(F18,[1]Sheet1!$A$2:$A$1238,0)),0) -> 17711.301 | H18: =LN(G18/G17) -> -0.0021037195 | N18: Regression | O18: 1 | P18: 0.090336911 | Q18: 0.090336911 | R18: 460.06715 | S18: 5.3650246e-87
B19: 44469 | C19: =IFERROR(INDEX(Sheet1!F15:F1255,MATCH(Mean_Rev!B19,Sheet1!A15:A1255,0)),0) -> 1459.0532 | D19: =LN(C19/C18) -> -0.010126454 | F19: =B19 -> 44469 | G19: =IFERROR(INDEX([1]Sheet1!$F$2:$F$1238,MATCH(F19,[1]Sheet1!$A$2:$A$1238,0)),0) -> 17618.15 | H19: =LN(G19/G18) -> -0.0052732552 | N19: Residual | O19: 1234 | P19: 0.24230321 | Q19: 0.00019635592
B20: 44470 | C20: =IFERROR(INDEX(Sheet1!F16:F1256,MATCH(Mean_Rev!B20,Sheet1!A16:A1256,0)),0) -> 1450.3 | D20: =LN(C20/C19) -> -0.0060172825 | F20: =B20 -> 44470 | G20: =IFERROR(INDEX([1]Sheet1!$F$2:$F$1238,MATCH(F20,[1]Sheet1!$A$2:$A$1238,0)),0) -> 17532.051 | H20: =LN(G20/G19) -> -0.0048989638 | N20: Total | O20: 1235 | P20: 0.33264012
B21: 44473 | C21: =IFERROR(INDEX(Sheet1!F17:F1257,MATCH(Mean_Rev!B21,Sheet1!A17:A1257,0)),0) -> 1462.1451 | D21: =LN(C21/C20) -> 0.0081341672 | F21: =B21 -> 44473 | G21: =IFERROR(INDEX([1]Sheet1!$F$2:$F$1238,MATCH(F21,[1]Sheet1!$A$2:$A$1238,0)),0) -> 17691.25 | H21: =LN(G21/G20) -> 0.009039488
B22: 44474 | C22: =IFERROR(INDEX(Sheet1!F18:F1258,MATCH(Mean_Rev!B22,Sheet1!A18:A1258,0)),0) -> 1474.3824 | D22: =LN(C22/C21) -> 0.0083345892 | F22: =B22 -> 44474 | G22: =IFERROR(INDEX([1]Sheet1!$F$2:$F$1238,MATCH(F22,[1]Sheet1!$A$2:$A$1238,0)),0) -> 17822.301 | H22: =LN(G22/G21) -> 0.0073803589 | O22: Coefficients | P22: Standard Error | Q22: t Stat | R22: P-value | S22: Lower 95% | T22: Upper 95% | U22: Lower 95.0% | V22: Upper 95.0%
B23: 44475 | C23: =IFERROR(INDEX(Sheet1!F19:F1259,MATCH(Mean_Rev!B23,Sheet1!A19:A1259,0)),0) -> 1457.6161 | D23: =LN(C23/C22) -> -0.011436936 | F23: =B23 -> 44475 | G23: =IFERROR(INDEX([1]Sheet1!$F$2:$F$1238,MATCH(F23,[1]Sheet1!$A$2:$A$1238,0)),0) -> 17646 | H23: =LN(G23/G22) -> -0.0099413972 | N23: Intercept | O23: -0.00052104834 | P23: 0.00039873102 | Q23: -1.3067665 | R23: 0.1915355 | S23: -0.001303314 | T23: 0.00026121736 | U23: -0.001303314 | V23: 0.00026121736
B24: 44476 | C24: =IFERROR(INDEX(Sheet1!F20:F1260,MATCH(Mean_Rev!B24,Sheet1!A20:A1260,0)),0) -> 1472.8146 | D24: =LN(C24/C23) -> 0.010372962 | F24: =B24 -> 44476 | G24: =IFERROR(INDEX([1]Sheet1!$F$2:$F$1238,MATCH(F24,[1]Sheet1!$A$2:$A$1238,0)),0) -> 17790.35 | H24: =LN(G24/G23) -> 0.0081470247 | N24: X Variable 1 | O24: 0.98178528 | P24: 0.045772634 | Q24: 21.449176 | R24: 5.3650246e-87 | S24: 0.89198448 | T24: 1.0715861 | U24: 0.89198448 | V24: 1.0715861
B25: 44477 | C25: =IFERROR(INDEX(Sheet1!F21:F1261,MATCH(Mean_Rev!B25,Sheet1!A21:A1261,0)),0) -> 1501.4259 | D25: =LN(C25/C24) -> 0.019240012 | F25: =B25 -> 44477 | G25: =IFERROR(INDEX([1]Sheet1!$F$2:$F$1238,MATCH(F25,[1]Sheet1!$A$2:$A$1238,0)),0) -> 17895.199 | H25: =LN(G25/G24) -> 0.0058763233
B26: 44480 | C26: =IFERROR(INDEX(Sheet1!F22:F1262,MATCH(Mean_Rev!B26,Sheet1!A22:A1262,0)),0) -> 1472.7709 | D26: =LN(C26/C25) -> -0.019269684 | F26: =B26 -> 44480 | G26: =IFERROR(INDEX([1]Sheet1!$F$2:$F$1238,MATCH(F26,[1]Sheet1!$A$2:$A$1238,0)),0) -> 17945.949 | H26: =LN(G26/G25) -> 0.0028319424
B27: 44481 | C27: =IFERROR(INDEX(Sheet1!F23:F1263,MATCH(Mean_Rev!B27,Sheet1!A23:A1263,0)),0) -> 1467.7194 | D27: =LN(C27/C26) -> -0.0034358343 | F27: =B27 -> 44481 | G27: =IFERROR(INDEX([1]Sheet1!$F$2:$F$1238,MATCH(F27,[1]Sheet1!$A$2:$A$1238,0)),0) -> 17991.949 | H27: =LN(G27/G26) -> 0.002559973
B28: 44482 | C28: =IFERROR(INDEX(Sheet1!F24:F1264,MATCH(Mean_Rev!B28,Sheet1!A24:A1264,0)),0) -> 1488.6661 | D28: =LN(C28/C27) -> 0.014170769 | F28: =B28 -> 44482 | G28: =IFERROR(INDEX([1]Sheet1!$F$2:$F$1238,MATCH(F28,[1]Sheet1!$A$2:$A$1238,0)),0) -> 18161.75 | H28: =LN(G28/G27) -> 0.009393342
B29: 44483 | C29: =IFERROR(INDEX(Sheet1!F25:F1265,MATCH(Mean_Rev!B29,Sheet1!A25:A1265,0)),0) -> 1494.3711 | D29: =LN(C29/C28) -> 0.0038249358 | F29: =B29 -> 44483 | G29: =IFERROR(INDEX([1]Sheet1!$F$2:$F$1238,MATCH(F29,[1]Sheet1!$A$2:$A$1238,0)),0) -> 18338.551 | H29: =LN(G29/G28) -> 0.00968771
B30: 44487 | C30: =IFERROR(INDEX(Sheet1!F26:F1266,MATCH(Mean_Rev!B30,Sheet1!A26:A1266,0)),0) -> 1560.9135 | D30: =LN(C30/C29) -> 0.043565751 | F30: =B30 -> 44487 | G30: =IFERROR(INDEX([1]Sheet1!$F$2:$F$1238,MATCH(F30,[1]Sheet1!$A$2:$A$1238,0)),0) -> 18477.051 | H30: =LN(G30/G29) -> 0.0075240196
B31: 44488 | C31: =IFERROR(INDEX(Sheet1!F27:F1267,MATCH(Mean_Rev!B31,Sheet1!A27:A1267,0)),0) -> 1587.0426 | D31: =LN(C31/C30) -> 0.01660109 | F31: =B31 -> 44488 | G31: =IFERROR(INDEX([1]Sheet1!$F$2:$F$1238,MATCH(F31,[1]Sheet1!$A$2:$A$1238,0)),0) -> 18418.75 | H31: =LN(G31/G30) -> -0.0031602962
B32: 44489 | C32: =IFERROR(INDEX(Sheet1!F28:F1268,MATCH(Mean_Rev!B32,Sheet1!A28:A1268,0)),0) -> 1569.7971 | D32: =LN(C32/C31) -> -0.010925898 | F32: =B32 -> 44489 | G32: =IFERROR(INDEX([1]Sheet1!$F$2:$F$1238,MATCH(F32,[1]Sheet1!$A$2:$A$1238,0)),0) -> 18266.6 | H32: =LN(G32/G31) -> -0.0082949332
B33: 44490 | C33: =IFERROR(INDEX(Sheet1!F29:F1269,MATCH(Mean_Rev!B33,Sheet1!A29:A1269,0)),0) -> 1527.3807 | D33: =LN(C33/C32) -> -0.027392056 | F33: =B33 -> 44490 | G33: =IFERROR(INDEX([1]Sheet1!$F$2:$F$1238,MATCH(F33,[1]Sheet1!$A$2:$A$1238,0)),0) -> 18178.1 | H33: =LN(G33/G32) -> -0.0048566829
B34: 44491 | C34: =IFERROR(INDEX(Sheet1!F30:F1270,MATCH(Mean_Rev!B34,Sheet1!A30:A1270,0)),0) -> 1497.8987 | D34: =LN(C34/C33) -> -0.019491085 | F34: =B34 -> 44491 | G34: =IFERROR(INDEX([1]Sheet1!$F$2:$F$1238,MATCH(F34,[1]Sheet1!$A$2:$A$1238,0)),0) -> 18114.9 | H34: =LN(G34/G33) -> -0.0034827257
B35: 44494 | C35: =IFERROR(INDEX(Sheet1!F31:F1271,MATCH(Mean_Rev!B35,Sheet1!A31:A1271,0)),0) -> 1487.2291 | D35: =LN(C35/C34) -> -0.0071485054 | F35: =B35 -> 44494 | G35: =IFERROR(INDEX([1]Sheet1!$F$2:$F$1238,MATCH(F35,[1]Sheet1!$A$2:$A$1238,0)),0) -> 18125.4 | H35: =LN(G35/G34) -> 0.00057946541
B36: 44495 | C36: =IFERROR(INDEX(Sheet1!F32:F1272,MATCH(Mean_Rev!B36,Sheet1!A32:A1272,0)),0) -> 1497.0267 | D36: =LN(C36/C35) -> 0.0065662216 | F36: =B36 -> 44495 | G36: =IFERROR(INDEX([1]Sheet1!$F$2:$F$1238,MATCH(F36,[1]Sheet1!$A$2:$A$1238,0)),0) -> 18268.4 | H36: =LN(G36/G35) -> 0.0078585217
... B1080: 46036 | C1080: =IFERROR(INDEX(Sheet1!F1076:F2316,MATCH(Mean_Rev!B1080,Sheet1!A1076:A2316,0)),0) -> 1565.9146 | D1080: =LN(C1080/C1079) -> 0.00050020413 | F1080: =B1080 -> 46036 | G1080: =IFERROR(INDEX([1]Sheet1!$F$2:$F$1238,MATCH(F1080,[1]Sheet1!$A$2:$A$1238,0)),0) -> 25665.6 | H1080: =LN(G1080/G1079) -> -0.0025954838
B1081: 46038 | C1081: =IFERROR(INDEX(Sheet1!F1078:F2318,MATCH(Mean_Rev!B1081,Sheet1!A1078:A2318,0)),0) -> 1654.0083 | D1081: =LN(C1081/C1080) -> 0.054731584 | F1081: =B1081 -> 46038 | G1081: =IFERROR(INDEX([1]Sheet1!$F$2:$F$1238,MATCH(F1081,[1]Sheet1!$A$2:$A$1238,0)),0) -> 25694.35 | H1081: =LN(G1081/G1080) -> 0.0011195495
B1082: 46041 | C1082: =IFERROR(INDEX(Sheet1!F1079:F2319,MATCH(Mean_Rev!B1082,Sheet1!A1079:A2319,0)),0) -> 1645.5903 | D1082: =LN(C1082/C1081) -> -0.0051024309 | F1082: =B1082 -> 46041 | G1082: =IFERROR(INDEX([1]Sheet1!$F$2:$F$1238,MATCH(F1082,[1]Sheet1!$A$2:$A$1238,0)),0) -> 25585.5 | H1082: =LN(G1082/G1081) -> -0.0042453234
B1083: 46042 | C1083: =IFERROR(INDEX(Sheet1!F1080:F2320,MATCH(Mean_Rev!B1083,Sheet1!A1080:A2320,0)),0) -> 1623.7628 | D1083: =LN(C1083/C1082) -> -0.013353002 | F1083: =B1083 -> 46042 | G1083: =IFERROR(INDEX([1]Sheet1!$F$2:$F$1238,MATCH(F1083,[1]Sheet1!$A$2:$A$1238,0)),0) -> 25232.5 | H1083: =LN(G1083/G1082) -> -0.013892939
B1084: 46043 | C1084: =IFERROR(INDEX(Sheet1!F1081:F2321,MATCH(Mean_Rev!B1084,Sheet1!A1081:A2321,0)),0) -> 1619.3582 | D1084: =LN(C1084/C1083) -> -0.002716313 | F1084: =B1084 -> 46043 | G1084: =IFERROR(INDEX([1]Sheet1!$F$2:$F$1238,MATCH(F1084,[1]Sheet1!$A$2:$A$1238,0)),0) -> 25157.5 | H1084: =LN(G1084/G1083) -> -0.0029767833
B1085: 46044 | C1085: =IFERROR(INDEX(Sheet1!F1082:F2322,MATCH(Mean_Rev!B1085,Sheet1!A1082:A2322,0)),0) -> 1628.2654 | D1085: =LN(C1085/C1084) -> 0.005485395 | F1085: =B1085 -> 46044 | G1085: =IFERROR(INDEX([1]Sheet1!$F$2:$F$1238,MATCH(F1085,[1]Sheet1!$A$2:$A$1238,0)),0) -> 25289.9 | H1085: =LN(G1085/G1084) -> 0.0052490592
...
