Workbook

Sheet Sheet1
A1: Date | B1: Open | C1: High | D1: Low | E1: Close | F1: Adj Close | G1: Volume
A2: 44452 | B2: 3767 | C2: 3852.3999 | D2: 3767 | E2: 3845.3501 | F2: 3340.45 | G2: 1691473
A3: 44453 | B3: 3849.95 | C3: 3896.5 | D3: 3825 | E3: 3885.8999 | F3: 3375.6748 | G3: 1991188
A4: 44454 | B4: 3882.1001 | C4: 3980 | D4: 3866 | E4: 3954.55 | F4: 3435.312 | G4: 2461369
A5: 44455 | B5: 3930 | C5: 3981.75 | D5: 3892.1001 | E5: 3903.3 | F5: 3390.7905 | G5: 2946666
A6: 44456 | B6: 3920 | C6: 3945 | D6: 3805 | E6: 3827.8501 | F6: 3325.2478 | G6: 6477148
A7: 44459 | B7: 3809 | C7: 3871 | D7: 3807.8501 | E7: 3823.5 | F7: 3321.4688 | G7: 2002008
A8: 44460 | B8: 3858 | C8: 3871.55 | D8: 3821.6499 | E8: 3862.95 | F8: 3355.7383 | G8: 1568129
A9: 44461 | B9: 3862.5 | C9: 3896.8501 | D9: 3852.45 | E9: 3862.1499 | F9: 3355.0437 | G9: 1744067
A10: 44462 | B10: 3870 | C10: 3879 | D10: 3835 | E10: 3869.25 | F10: 3361.2117 | G10: 2003869
A11: 44463 | B11: 3890 | C11: 3944.3999 | D11: 3855 | E11: 3871.3 | F11: 3362.9927 | G11: 2320754
A12: 44466 | B12: 3900 | C12: 3904 | D12: 3802.8999 | E12: 3836.95 | F12: 3333.1521 | G12: 1673362
A13: 44467 | B13: 3850 | C13: 3850 | D13: 3751.25 | E13: 3779.1499 | F13: 3282.9419 | G13: 2253075
... A1242: 46276 | B1242: 2185.5 | C1242: 2232.6001 | D1242: 2185.5 | E1242: 2200.8 | F1242: 2200.8 | G1242: 2633119

Sheet Mean_Rev
B2: Regression Beta - 5Years Daily
B4: TCS Return | F4: Nifty50 Return
B5: Date | C5: Close Price | D5: Return | F5: Date | G5: Close Price | H5: Return
B6: 44452 | C6: =IFERROR(INDEX(Sheet1!F2:F1242,MATCH(Mean_Rev!B6,Sheet1!A2:A1242,0)),0) -> 3340.45 | F6: =B6 -> 44452 | G6: =IFERROR(INDEX([1]Sheet1!$F$2:$F$1238,MATCH(F6,[1]Sheet1!$A$2:$A$1238,0)),0) -> 17355.301
B7: 44453 | C7: =IFERROR(INDEX(Sheet1!F3:F1243,MATCH(Mean_Rev!B7,Sheet1!A3:A1243,0)),0) -> 3375.6748 | D7: =LN(C7/C6) -> 0.010489733 | F7: =B7 -> 44453 | G7: =IFERROR(INDEX([1]Sheet1!$F$2:$F$1238,MATCH(F7,[1]Sheet1!$A$2:$A$1238,0)),0) -> 17380 | H7: =LN(G7/G6) -> 0.0014221396
B8: 44454 | C8: =IFERROR(INDEX(Sheet1!F4:F1244,MATCH(Mean_Rev!B8,Sheet1!A4:A1244,0)),0) -> 3435.312 | D8: =LN(C8/C7) -> 0.017512508 | F8: =B8 -> 44454 | G8: =IFERROR(INDEX([1]Sheet1!$F$2:$F$1238,MATCH(F8,[1]Sheet1!$A$2:$A$1238,0)),0) -> 17519.449 | H8: =LN(G8/G7) -> 0.0079915279 | K8: Beta Drafting | O8: SUMMARY OUTPUT
B9: 44455 | C9: =IFERROR(INDEX(Sheet1!F5:F1245,MATCH(Mean_Rev!B9,Sheet1!A5:A1245,0)),0) -> 3390.7905 | D9: =LN(C9/C8) -> -0.013044667 | F9: =B9 -> 44455 | G9: =IFERROR(INDEX([1]Sheet1!$F$2:$F$1238,MATCH(F9,[1]Sheet1!$A$2:$A$1238,0)),0) -> 17629.5 | H9: =LN(G9/G8) -> 0.0062619875
B10: 44456 | C10: =IFERROR(INDEX(Sheet1!F6:F1246,MATCH(Mean_Rev!B10,Sheet1!A6:A1246,0)),0) -> 3325.2478 | D10: =LN(C10/C9) -> -0.01951889 | F10: =B10 -> 44456 | G10: =IFERROR(INDEX([1]Sheet1!$F$2:$F$1238,MATCH(F10,[1]Sheet1!$A$2:$A$1238,0)),0) -> 17585.15 | H10: =LN(G10/G9) -> -0.0025188172 | O10: Regression Statistics
B11: 44459 | C11: =IFERROR(INDEX(Sheet1!F7:F1247,MATCH(Mean_Rev!B11,Sheet1!A7:A1247,0)),0) -> 3321.4688 | D11: =LN(C11/C10) -> -0.0011371188 | F11: =B11 -> 44459 | G11: =IFERROR(INDEX([1]Sheet1!$F$2:$F$1238,MATCH(F11,[1]Sheet1!$A$2:$A$1238,0)),0) -> 17396.9 | H11: =LN(G11/G10) -> -0.010762766 | K11: Levered Raw Beta | L11: =P25 -> 0.81931962 | O11: Multiple R | P11: 0.50218753
B12: 44460 | C12: =IFERROR(INDEX(Sheet1!F8:F1248,MATCH(Mean_Rev!B12,Sheet1!A8:A1248,0)),0) -> 3355.7383 | D12: =LN(C12/C11) -> 0.010264721 | F12: =B12 -> 44460 | G12: =IFERROR(INDEX([1]Sheet1!$F$2:$F$1238,MATCH(F12,[1]Sheet1!$A$2:$A$1238,0)),0) -> 17562 | H12: =LN(G12/G11) -> 0.0094454251 | K12: Raw Beta Weight | L12: 0.75 | O12: R Square | P12: 0.25219231
B13: 44461 | C13: =IFERROR(INDEX(Sheet1!F9:F1249,MATCH(Mean_Rev!B13,Sheet1!A9:A1249,0)),0) -> 3355.0437 | D13: =LN(C13/C12) -> -0.00020700422 | F13: =B13 -> 44461 | G13: =IFERROR(INDEX([1]Sheet1!$F$2:$F$1238,MATCH(F13,[1]Sheet1!$A$2:$A$1238,0)),0) -> 17546.65 | H13: =LN(G13/G12) -> -0.00087440618 | O13: Adjusted R Square | P13: 0.25158631
B14: 44462 | C14: =IFERROR(INDEX(Sheet1!F10:F1250,MATCH(Mean_Rev!B14,Sheet1!A10:A1250,0)),0) -> 3361.2117 | D14: =LN(C14/C13) -> 0.001836729 | F14: =B14 -> 44462 | G14: =IFERROR(INDEX([1]Sheet1!$F$2:$F$1238,MATCH(F14,[1]Sheet1!$A$2:$A$1238,0)),0) -> 17822.949 | H14: =LN(G14/G13) -> 0.015623838 | K14: Market Beta | L14: 1 | O14: Standard Error | P14: 0.012295351
B15: 44463 | C15: =IFERROR(INDEX(Sheet1!F11:F1251,MATCH(Mean_Rev!B15,Sheet1!A11:A1251,0)),0) -> 3362.9927 | D15: =LN(C15/C14) -> 0.00052972986 | F15: =B15 -> 44463 | G15: =IFERROR(INDEX([1]Sheet1!$F$2:$F$1238,MATCH(F15,[1]Sheet1!$A$2:$A$1238,0)),0) -> 17853.199 | H15: =LN(G15/G14) -> 0.0016958113 | K15: Market Beta Weight | L15: 0.25 | O15: Observations | P15: 1236
B16: 44466 | C16: =IFERROR(INDEX(Sheet1!F12:F1252,MATCH(Mean_Rev!B16,Sheet1!A12:A1252,0)),0) -> 3333.1521 | D16: =LN(C16/C15) -> -0.0089128221 | F16: =B16 -> 44466 | G16: =IFERROR(INDEX([1]Sheet1!$F$2:$F$1238,MATCH(F16,[1]Sheet1!$A$2:$A$1238,0)),0) -> 17855.1 | H16: =LN(G16/G15) -> 0.00010643972
B17: 44467 | C17: =IFERROR(INDEX(Sheet1!F13:F1253,MATCH(Mean_Rev!B17,Sheet1!A13:A1253,0)),0) -> 3282.9419 | D17: =LN(C17/C16) -> -0.015178493 | F17: =B17 -> 44467 | G17: =IFERROR(INDEX([1]Sheet1!$F$2:$F$1238,MATCH(F17,[1]Sheet1!$A$2:$A$1238,0)),0) -> 17748.6 | H17: =LN(G17/G16) -> -0.0059825423 | K17: Adjusted Beta | L17: =(L11*L12)+(L14*L15) -> 0.86448972 | O17: ANOVA
B18: 44468 | C18: =IFERROR(INDEX(Sheet1!F14:F1254,MATCH(Mean_Rev!B18,Sheet1!A14:A1254,0)),0) -> 3294.0176 | D18: =LN(C18/C17) -> 0.0033680287 | F18: =B18 -> 44468 | G18: =IFERROR(INDEX([1]Sheet1!$F$2:$F$1238,MATCH(F18,[1]Sheet1!$A$2:$A$1238,0)),0) -> 17711.301 | H18: =LN(G18/G17) -> -0.0021037195 | P18: df | Q18: SS | R18: MS | S18: F | T18: Significance F
B19: 44469 | C19: =IFERROR(INDEX(Sheet1!F15:F1255,MATCH(Mean_Rev!B19,Sheet1!A15:A1255,0)),0) -> 3279.8145 | D19: =LN(C19/C18) -> -0.0043211165 | F19: =B19 -> 44469 | G19: =IFERROR(INDEX([1]Sheet1!$F$2:$F$1238,MATCH(F19,[1]Sheet1!$A$2:$A$1238,0)),0) -> 17618.15 | H19: =LN(G19/G18) -> -0.0052732552 | O19: Regression | P19: 1 | Q19: 0.062912787 | R19: 0.062912787 | S19: 416.15688 | T19: 6.0628562e-80
B20: 44470 | C20: =IFERROR(INDEX(Sheet1!F16:F1256,MATCH(Mean_Rev!B20,Sheet1!A16:A1256,0)),0) -> 3240.4189 | D20: =LN(C20/C19) -> -0.012084226 | F20: =B20 -> 44470 | G20: =IFERROR(INDEX([1]Sheet1!$F$2:$F$1238,MATCH(F20,[1]Sheet1!$A$2:$A$1238,0)),0) -> 17532.051 | H20: =LN(G20/G19) -> -0.0048989638 | O20: Residual | P20: 1234 | Q20: 0.18655075 | R20: 0.00015117565
B21: 44473 | C21: =IFERROR(INDEX(Sheet1!F17:F1257,MATCH(Mean_Rev!B21,Sheet1!A17:A1257,0)),0) -> 3277.8596 | D21: =LN(C21/C20) -> 0.011488029 | F21: =B21 -> 44473 | G21: =IFERROR(INDEX([1]Sheet1!$F$2:$F$1238,MATCH(F21,[1]Sheet1!$A$2:$A$1238,0)),0) -> 17691.25 | H21: =LN(G21/G20) -> 0.009039488 | O21: Total | P21: 1235 | Q21: 0.24946354
B22: 44474 | C22: =IFERROR(INDEX(Sheet1!F18:F1258,MATCH(Mean_Rev!B22,Sheet1!A18:A1258,0)),0) -> 3329.9819 | D22: =LN(C22/C21) -> 0.015776224 | F22: =B22 -> 44474 | G22: =IFERROR(INDEX([1]Sheet1!$F$2:$F$1238,MATCH(F22,[1]Sheet1!$A$2:$A$1238,0)),0) -> 17822.301 | H22: =LN(G22/G21) -> 0.0073803589
B23: 44475 | C23: =IFERROR(INDEX(Sheet1!F19:F1259,MATCH(Mean_Rev!B23,Sheet1!A19:A1259,0)),0) -> 3310.5225 | D23: =LN(C23/C22) -> -0.0058608585 | F23: =B23 -> 44475 | G23: =IFERROR(INDEX([1]Sheet1!$F$2:$F$1238,MATCH(F23,[1]Sheet1!$A$2:$A$1238,0)),0) -> 17646 | H23: =LN(G23/G22) -> -0.0099413972 | P23: Coefficients | Q23: Standard Error | R23: t Stat | S23: P-value | T23: Lower 95% | U23: Upper 95% | V23: Lower 95.0% | W23: Upper 95.0%
B24: 44476 | C24: =IFERROR(INDEX(Sheet1!F20:F1260,MATCH(Mean_Rev!B24,Sheet1!A20:A1260,0)),0) -> 3381.7559 | D24: =LN(C24/C23) -> 0.02128904 | F24: =B24 -> 44476 | G24: =IFERROR(INDEX([1]Sheet1!$F$2:$F$1238,MATCH(F24,[1]Sheet1!$A$2:$A$1238,0)),0) -> 17790.35 | H24: =LN(G24/G23) -> 0.0081470247 | O24: Intercept | P24: -0.00053564878 | Q24: 0.00034986374 | R24: -1.5310211 | S24: 0.12602048 | T24: -0.0012220424 | U24: 0.00015074479 | V24: -0.0012220424 | W24: 0.00015074479
B25: 44477 | C25: =IFERROR(INDEX(Sheet1!F21:F1261,MATCH(Mean_Rev!B25,Sheet1!A21:A1261,0)),0) -> 3418.8926 | D25: =LN(C25/C24) -> 0.010921631 | F25: =B25 -> 44477 | G25: =IFERROR(INDEX([1]Sheet1!$F$2:$F$1238,MATCH(F25,[1]Sheet1!$A$2:$A$1238,0)),0) -> 17895.199 | H25: =LN(G25/G24) -> 0.0058763233 | O25: X Variable 1 | P25: 0.81931962 | Q25: 0.040162877 | R25: 20.399923 | S25: 6.0628562e-80 | T25: 0.74052455 | U25: 0.8981147 | V25: 0.74052455 | W25: 0.8981147
B26: 44480 | C26: =IFERROR(INDEX(Sheet1!F22:F1262,MATCH(Mean_Rev!B26,Sheet1!A22:A1262,0)),0) -> 3201.6753 | D26: =LN(C26/C25) -> -0.065642489 | F26: =B26 -> 44480 | G26: =IFERROR(INDEX([1]Sheet1!$F$2:$F$1238,MATCH(F26,[1]Sheet1!$A$2:$A$1238,0)),0) -> 17945.949 | H26: =LN(G26/G25) -> 0.0028319424
B27: 44481 | C27: =IFERROR(INDEX(Sheet1!F23:F1263,MATCH(Mean_Rev!B27,Sheet1!A23:A1263,0)),0) -> 3173.2251 | D27: =LN(C27/C26) -> -0.0089257502 | F27: =B27 -> 44481 | G27: =IFERROR(INDEX([1]Sheet1!$F$2:$F$1238,MATCH(F27,[1]Sheet1!$A$2:$A$1238,0)),0) -> 17991.949 | H27: =LN(G27/G26) -> 0.002559973
B28: 44482 | C28: =IFERROR(INDEX(Sheet1!F24:F1264,MATCH(Mean_Rev!B28,Sheet1!A24:A1264,0)),0) -> 3175.2666 | D28: =LN(C28/C27) -> 0.00064314614 | F28: =B28 -> 44482 | G28: =IFERROR(INDEX([1]Sheet1!$F$2:$F$1238,MATCH(F28,[1]Sheet1!$A$2:$A$1238,0)),0) -> 18161.75 | H28: =LN(G28/G27) -> 0.009393342
B29: 44483 | C29: =IFERROR(INDEX(Sheet1!F25:F1265,MATCH(Mean_Rev!B29,Sheet1!A25:A1265,0)),0) -> 3143.2805 | D29: =LN(C29/C28) -> -0.010124592 | F29: =B29 -> 44483 | G29: =IFERROR(INDEX([1]Sheet1!$F$2:$F$1238,MATCH(F29,[1]Sheet1!$A$2:$A$1238,0)),0) -> 18338.551 | H29: =LN(G29/G28) -> 0.00968771 | O29: RESIDUAL OUTPUT
B30: 44487 | C30: =IFERROR(INDEX(Sheet1!F26:F1266,MATCH(Mean_Rev!B30,Sheet1!A26:A1266,0)),0) -> 3174.3525 | D30: =LN(C30/C29) -> 0.0098366815 | F30: =B30 -> 44487 | G30: =IFERROR(INDEX([1]Sheet1!$F$2:$F$1238,MATCH(F30,[1]Sheet1!$A$2:$A$1238,0)),0) -> 18477.051 | H30: =LN(G30/G29) -> 0.0075240196
B31: 44488 | C31: =IFERROR(INDEX(Sheet1!F27:F1267,MATCH(Mean_Rev!B31,Sheet1!A27:A1267,0)),0) -> 3163.0381 | D31: =LN(C31/C30) -> -0.0035707015 | F31: =B31 -> 44488 | G31: =IFERROR(INDEX([1]Sheet1!$F$2:$F$1238,MATCH(F31,[1]Sheet1!$A$2:$A$1238,0)),0) -> 18418.75 | H31: =LN(G31/G30) -> -0.0031602962 | O31: Observation | P31: Predicted Y | Q31: Residuals
B32: 44489 | C32: =IFERROR(INDEX(Sheet1!F28:F1268,MATCH(Mean_Rev!B32,Sheet1!A28:A1268,0)),0) -> 3141.0186 | D32: =LN(C32/C31) -> -0.0069858575 | F32: =B32 -> 44489 | G32: =IFERROR(INDEX([1]Sheet1!$F$2:$F$1238,MATCH(F32,[1]Sheet1!$A$2:$A$1238,0)),0) -> 18266.6 | H32: =LN(G32/G31) -> -0.0082949332 | O32: 1 | P32: 0.00062953808 | Q32: 0.0098601946
B33: 44490 | C33: =IFERROR(INDEX(Sheet1!F29:F1269,MATCH(Mean_Rev!B33,Sheet1!A29:A1269,0)),0) -> 3074.5657 | D33: =LN(C33/C32) -> -0.021383481 | F33: =B33 -> 44490 | G33: =IFERROR(INDEX([1]Sheet1!$F$2:$F$1238,MATCH(F33,[1]Sheet1!$A$2:$A$1238,0)),0) -> 18178.1 | H33: =LN(G33/G32) -> -0.0048566829 | O33: 2 | P33: 0.0060119669 | Q33: 0.011500541
B34: 44491 | C34: =IFERROR(INDEX(Sheet1!F30:F1270,MATCH(Mean_Rev!B34,Sheet1!A30:A1270,0)),0) -> 3045.2778 | D34: =LN(C34/C33) -> -0.009571508 | F34: =B34 -> 44491 | G34: =IFERROR(INDEX([1]Sheet1!$F$2:$F$1238,MATCH(F34,[1]Sheet1!$A$2:$A$1238,0)),0) -> 18114.9 | H34: =LN(G34/G33) -> -0.0034827257 | O34: 3 | P34: 0.0045949205 | Q34: -0.017639587
B35: 44494 | C35: =IFERROR(INDEX(Sheet1!F31:F1271,MATCH(Mean_Rev!B35,Sheet1!A31:A1271,0)),0) -> 3040.1428 | D35: =LN(C35/C34) -> -0.0016876437 | F35: =B35 -> 44494 | G35: =IFERROR(INDEX([1]Sheet1!$F$2:$F$1238,MATCH(F35,[1]Sheet1!$A$2:$A$1238,0)),0) -> 18125.4 | H35: =LN(G35/G34) -> 0.00057946541 | O35: 4 | P35: -0.0025993651 | Q35: -0.016919525
B36: 44495 | C36: =IFERROR(INDEX(Sheet1!F32:F1272,MATCH(Mean_Rev!B36,Sheet1!A32:A1272,0)),0) -> 3031.1348 | D36: =LN(C36/C35) -> -0.0029674358 | F36: =B36 -> 44495 | G36: =IFERROR(INDEX([1]Sheet1!$F$2:$F$1238,MATCH(F36,[1]Sheet1!$A$2:$A$1238,0)),0) -> 18268.4 | H36: =LN(G36/G35) -> 0.0078585217 | O36: 5 | P36: -0.0093537944 | Q36: 0.0082166756
B37: 44496 | C37: =IFERROR(INDEX(Sheet1!F33:F1273,MATCH(Mean_Rev!B37,Sheet1!A33:A1273,0)),0) -> 3037.3572 | D37: =LN(C37/C36) -> 0.0020507284 | F37: =B37 -> 44496 | G37: =IFERROR(INDEX([1]Sheet1!$F$2:$F$1238,MATCH(F37,[1]Sheet1!$A$2:$A$1238,0)),0) -> 18210.949 | H37: =LN(G37/G36) -> -0.0031497941 | O37: 6 | P37: 0.0072031733 | Q37: 0.0030615472
B38: 44497 | C38: =IFERROR(INDEX(Sheet1!F34:F1274,MATCH(Mean_Rev!B38,Sheet1!A34:A1274,0)),0) -> 2978.0854 | D38: =LN(C38/C37) -> -0.019707161 | F38: =B38 -> 44497 | G38: =IFERROR(INDEX([1]Sheet1!$F$2:$F$1238,MATCH(F38,[1]Sheet1!$A$2:$A$1238,0)),0) -> 17857.25 | H38: =LN(G38/G37) -> -0.01961343 | O38: 7 | P38: -0.0012520669 | Q38: 0.0010450627
B39: 44498 | C39: =IFERROR(INDEX(Sheet1!F35:F1275,MATCH(Mean_Rev!B39,Sheet1!A35:A1275,0)),0) -> 2957.2834 | D39: =LN(C39/C38) -> -0.0070095347 | F39: =B39 -> 44498 | G39: =IFERROR(INDEX([1]Sheet1!$F$2:$F$1238,MATCH(F39,[1]Sheet1!$A$2:$A$1238,0)),0) -> 17671.65 | H39: =LN(G39/G38) -> -0.010447906 | O39: 8 | P39: 0.012265268 | Q39: -0.010428539
B40: 44501 | C40: =IFERROR(INDEX(Sheet1!F36:F1276,MATCH(Mean_Rev!B40,Sheet1!A36:A1276,0)),0) -> 3025.7375 | D40: =LN(C40/C39) -> 0.022883787 | F40: =B40 -> 44501 | G40: =IFERROR(INDEX([1]Sheet1!$F$2:$F$1238,MATCH(F40,[1]Sheet1!$A$2:$A$1238,0)),0) -> 17929.65 | H40: =LN(G40/G39) -> 0.014494106 | O40: 9 | P40: 0.00085376267 | Q40: -0.00032403282
B41: 44502 | C41: =IFERROR(INDEX(Sheet1!F37:F1277,MATCH(Mean_Rev!B41,Sheet1!A37:A1277,0)),0) -> 3032.5269 | D41: =LN(C41/C40) -> 0.0022413381 | F41: =B41 -> 44502 | G41: =IFERROR(INDEX([1]Sheet1!$F$2:$F$1238,MATCH(F41,[1]Sheet1!$A$2:$A$1238,0)),0) -> 17888.949 | H41: =LN(G41/G40) -> -0.0022726287 | O41: 10 | P41: -0.00044844063 | Q41: -0.0084643815
B42: 44503 | C42: =IFERROR(INDEX(Sheet1!F38:F1278,MATCH(Mean_Rev!B42,Sheet1!A38:A1278,0)),0) -> 3039.5337 | D42: =LN(C42/C41) -> 0.002307895 | F42: =B42 -> 44503 | G42: =IFERROR(INDEX([1]Sheet1!$F$2:$F$1238,MATCH(F42,[1]Sheet1!$A$2:$A$1238,0)),0) -> 17829.199 | H42: =LN(G42/G41) -> -0.0033456413 | O42: 11 | P42: -0.0054372631 | Q42: -0.0097412302
...
