Workbook

Sheet Sheet1
A1: Date | B1: Open | C1: High | D1: Low | E1: Close | F1: Adj Close | G1: Volume
A2: 44452 | B2: 331.17499 | C2: 335.92499 | D2: 328.92499 | E2: 335.375 | F2: 306.35391 | G2: 11177578
A3: 44453 | B3: 335.5 | C3: 337.85001 | D3: 335 | E3: 336.72501 | F3: 307.5871 | G3: 7322676
A4: 44454 | B4: 337 | C4: 340.27499 | D4: 335 | E4: 337.02499 | F4: 307.86111 | G4: 8290832
A5: 44455 | B5: 339.875 | C5: 340.375 | D5: 332.5 | E5: 333.92499 | F5: 305.02939 | G5: 9315692
A6: 44456 | B6: 335.70001 | C6: 337.20001 | D6: 331.375 | E6: 332.625 | F6: 303.84186 | G6: 10815562
A7: 44459 | B7: 328.875 | C7: 335.25 | D7: 326.70001 | E7: 331.25 | F7: 302.58588 | G7: 9092860
A8: 44460 | B8: 330.25 | C8: 334.5 | D8: 328.54999 | E8: 333.79999 | F8: 304.91516 | G8: 7367102
A9: 44461 | B9: 334.5 | C9: 337.25 | D9: 331.5 | E9: 334.07501 | F9: 305.16641 | G9: 9583304
A10: 44462 | B10: 336.45001 | C10: 338.5 | D10: 335.70001 | E10: 337.14999 | F10: 307.97528 | G10: 6462586
A11: 44463 | B11: 340.25 | C11: 349.57501 | D11: 337.5 | E11: 338.25 | F11: 308.9801 | G11: 24253176
A12: 44466 | B12: 339.02499 | C12: 339.17499 | D12: 325.5 | E12: 326.95001 | F12: 298.65793 | G12: 16798164
A13: 44467 | B13: 326.95001 | C13: 326.95001 | D13: 317.625 | E13: 319.79999 | F13: 292.12665 | G13: 16224924
... A1242: 46276 | B1242: 165.2 | C1242: 167.75 | D1242: 165.16 | E1242: 167.39999 | F1242: 167.39999 | G1242: 8478180

Sheet Mean_rev
B3: Wipro Ltd | G3: Nifty50 Return
B5: Date | C5: Close Price | D5: Return | H5: Close Price | I5: Return
B6: 44452 | C6: =IFERROR(INDEX(Sheet1!F2:F1242,MATCH(Mean_rev!B6,Sheet1!A2:A1242,0)),0) -> 306.35391 | G6: =B6 -> 44452 | H6: =IFERROR(INDEX([1]Sheet1!$F$2:$F$1238,MATCH(G6,[1]Sheet1!$A$2:$A$1238,0)),0) -> 17355.301
B7: 44453 | C7: =IFERROR(INDEX(Sheet1!F3:F1243,MATCH(Mean_rev!B7,Sheet1!A3:A1243,0)),0) -> 307.5871 | D7: =LN(C7/C6) -> 0.00401728 | G7: =B7 -> 44453 | H7: =IFERROR(INDEX([1]Sheet1!$F$2:$F$1238,MATCH(G7,[1]Sheet1!$A$2:$A$1238,0)),0) -> 17380 | I7: =LN(H7/H6) -> 0.0014221396 | K7: Beta Drafting | P7: SUMMARY OUTPUT
B8: 44454 | C8: =IFERROR(INDEX(Sheet1!F4:F1244,MATCH(Mean_rev!B8,Sheet1!A4:A1244,0)),0) -> 307.86111 | D8: =LN(C8/C7) -> 0.00089046437 | G8: =B8 -> 44454 | H8: =IFERROR(INDEX([1]Sheet1!$F$2:$F$1238,MATCH(G8,[1]Sheet1!$A$2:$A$1238,0)),0) -> 17519.449 | I8: =LN(H8/H7) -> 0.0079915279
B9: 44455 | C9: =IFERROR(INDEX(Sheet1!F5:F1245,MATCH(Mean_rev!B9,Sheet1!A5:A1245,0)),0) -> 305.02939 | D9: =LN(C9/C8) -> -0.0092406269 | G9: =B9 -> 44455 | H9: =IFERROR(INDEX([1]Sheet1!$F$2:$F$1238,MATCH(G9,[1]Sheet1!$A$2:$A$1238,0)),0) -> 17629.5 | I9: =LN(H9/H8) -> 0.0062619875 | P9: Regression Statistics
B10: 44456 | C10: =IFERROR(INDEX(Sheet1!F6:F1246,MATCH(Mean_rev!B10,Sheet1!A6:A1246,0)),0) -> 303.84186 | D10: =LN(C10/C9) -> -0.0039007657 | G10: =B10 -> 44456 | H10: =IFERROR(INDEX([1]Sheet1!$F$2:$F$1238,MATCH(G10,[1]Sheet1!$A$2:$A$1238,0)),0) -> 17585.15 | I10: =LN(H10/H9) -> -0.0025188172 | K10: Levered Raw Beta | L10: =Q24 -> 0.99895348 | P10: Multiple R | Q10: 0.53942248
B11: 44459 | C11: =IFERROR(INDEX(Sheet1!F7:F1247,MATCH(Mean_rev!B11,Sheet1!A7:A1247,0)),0) -> 302.58588 | D11: =LN(C11/C10) -> -0.0041422355 | G11: =B11 -> 44459 | H11: =IFERROR(INDEX([1]Sheet1!$F$2:$F$1238,MATCH(G11,[1]Sheet1!$A$2:$A$1238,0)),0) -> 17396.9 | I11: =LN(H11/H10) -> -0.010762766 | K11: Raw Beta Weight | L11: 0.65 | P11: R Square | Q11: 0.29097662
B12: 44460 | C12: =IFERROR(INDEX(Sheet1!F8:F1248,MATCH(Mean_rev!B12,Sheet1!A8:A1248,0)),0) -> 304.91516 | D12: =LN(C12/C11) -> 0.0076684514 | G12: =B12 -> 44460 | H12: =IFERROR(INDEX([1]Sheet1!$F$2:$F$1238,MATCH(G12,[1]Sheet1!$A$2:$A$1238,0)),0) -> 17562 | I12: =LN(H12/H11) -> 0.0094454251 | P12: Adjusted R Square | Q12: 0.29040204
B13: 44461 | C13: =IFERROR(INDEX(Sheet1!F9:F1249,MATCH(Mean_rev!B13,Sheet1!A9:A1249,0)),0) -> 305.16641 | D13: =LN(C13/C12) -> 0.00082366439 | G13: =B13 -> 44461 | H13: =IFERROR(INDEX([1]Sheet1!$F$2:$F$1238,MATCH(G13,[1]Sheet1!$A$2:$A$1238,0)),0) -> 17546.65 | I13: =LN(H13/H12) -> -0.00087440618 | K13: Market Beta | L13: 1 | P13: Standard Error | Q13: 0.013589548
B14: 44462 | C14: =IFERROR(INDEX(Sheet1!F10:F1250,MATCH(Mean_rev!B14,Sheet1!A10:A1250,0)),0) -> 307.97528 | D14: =LN(C14/C13) -> 0.0091622804 | G14: =B14 -> 44462 | H14: =IFERROR(INDEX([1]Sheet1!$F$2:$F$1238,MATCH(G14,[1]Sheet1!$A$2:$A$1238,0)),0) -> 17822.949 | I14: =LN(H14/H13) -> 0.015623838 | K14: Market Beta Weight | L14: 0.35 | P14: Observations | Q14: 1236
B15: 44463 | C15: =IFERROR(INDEX(Sheet1!F11:F1251,MATCH(Mean_rev!B15,Sheet1!A11:A1251,0)),0) -> 308.9801 | D15: =LN(C15/C14) -> 0.0032573593 | G15: =B15 -> 44463 | H15: =IFERROR(INDEX([1]Sheet1!$F$2:$F$1238,MATCH(G15,[1]Sheet1!$A$2:$A$1238,0)),0) -> 17853.199 | I15: =LN(H15/H14) -> 0.0016958113
B16: 44466 | C16: =IFERROR(INDEX(Sheet1!F12:F1252,MATCH(Mean_rev!B16,Sheet1!A12:A1252,0)),0) -> 298.65793 | D16: =LN(C16/C15) -> -0.033978015 | G16: =B16 -> 44466 | H16: =IFERROR(INDEX([1]Sheet1!$F$2:$F$1238,MATCH(G16,[1]Sheet1!$A$2:$A$1238,0)),0) -> 17855.1 | I16: =LN(H16/H15) -> 0.00010643972 | K16: Adjusted Beta | L16: =(L10*L11)+(L13*L14) -> 0.99931977 | P16: ANOVA
B17: 44467 | C17: =IFERROR(INDEX(Sheet1!F13:F1253,MATCH(Mean_rev!B17,Sheet1!A13:A1253,0)),0) -> 292.12665 | D17: =LN(C17/C16) -> -0.022111432 | G17: =B17 -> 44467 | H17: =IFERROR(INDEX([1]Sheet1!$F$2:$F$1238,MATCH(G17,[1]Sheet1!$A$2:$A$1238,0)),0) -> 17748.6 | I17: =LN(H17/H16) -> -0.0059825423 | Q17: df | R17: SS | S17: MS | T17: F | U17: Significance F
B18: 44468 | C18: =IFERROR(INDEX(Sheet1!F14:F1254,MATCH(Mean_rev!B18,Sheet1!A14:A1254,0)),0) -> 292.65189 | D18: =LN(C18/C17) -> 0.0017963661 | G18: =B18 -> 44468 | H18: =IFERROR(INDEX([1]Sheet1!$F$2:$F$1238,MATCH(G18,[1]Sheet1!$A$2:$A$1238,0)),0) -> 17711.301 | I18: =LN(H18/H17) -> -0.0021037195 | P18: Regression | Q18: 1 | R18: 0.093523928 | S18: 0.093523928 | T18: 506.42215 | U18: 3.0267588e-94
B19: 44469 | C19: =IFERROR(INDEX(Sheet1!F15:F1255,MATCH(Mean_rev!B19,Sheet1!A15:A1255,0)),0) -> 289.61465 | D19: =LN(C19/C18) -> -0.010432538 | G19: =B19 -> 44469 | H19: =IFERROR(INDEX([1]Sheet1!$F$2:$F$1238,MATCH(G19,[1]Sheet1!$A$2:$A$1238,0)),0) -> 17618.15 | I19: =LN(H19/H18) -> -0.0052732552 | P19: Residual | Q19: 1234 | R19: 0.22788997 | S19: 0.00018467582
B20: 44470 | C20: =IFERROR(INDEX(Sheet1!F16:F1256,MATCH(Mean_rev!B20,Sheet1!A16:A1256,0)),0) -> 290.59662 | D20: =LN(C20/C19) -> 0.0033848534 | G20: =B20 -> 44470 | H20: =IFERROR(INDEX([1]Sheet1!$F$2:$F$1238,MATCH(G20,[1]Sheet1!$A$2:$A$1238,0)),0) -> 17532.051 | I20: =LN(H20/H19) -> -0.0048989638 | P20: Total | Q20: 1235 | R20: 0.3214139
B21: 44473 | C21: =IFERROR(INDEX(Sheet1!F17:F1257,MATCH(Mean_rev!B21,Sheet1!A17:A1257,0)),0) -> 292.78891 | D21: =LN(C21/C20) -> 0.0075157901 | G21: =B21 -> 44473 | H21: =IFERROR(INDEX([1]Sheet1!$F$2:$F$1238,MATCH(G21,[1]Sheet1!$A$2:$A$1238,0)),0) -> 17691.25 | I21: =LN(H21/H20) -> 0.009039488
B22: 44474 | C22: =IFERROR(INDEX(Sheet1!F18:F1258,MATCH(Mean_rev!B22,Sheet1!A18:A1258,0)),0) -> 295.43796 | D22: =LN(C22/C21) -> 0.0090069526 | G22: =B22 -> 44474 | H22: =IFERROR(INDEX([1]Sheet1!$F$2:$F$1238,MATCH(G22,[1]Sheet1!$A$2:$A$1238,0)),0) -> 17822.301 | I22: =LN(H22/H21) -> 0.0073803589 | Q22: Coefficients | R22: Standard Error | S22: t Stat | T22: P-value | U22: Lower 95% | V22: Upper 95% | W22: Lower 95.0% | X22: Upper 95.0%
B23: 44475 | C23: =IFERROR(INDEX(Sheet1!F19:F1259,MATCH(Mean_rev!B23,Sheet1!A19:A1259,0)),0) -> 290.36823 | D23: =LN(C23/C22) -> -0.017308999 | G23: =B23 -> 44475 | H23: =IFERROR(INDEX([1]Sheet1!$F$2:$F$1238,MATCH(G23,[1]Sheet1!$A$2:$A$1238,0)),0) -> 17646 | I23: =LN(H23/H22) -> -0.0099413972 | P23: Intercept | Q23: -0.00073041995 | R23: 0.00038669009 | S23: -1.8889027 | T23: 0.059139188 | U23: -0.0014890627 | V23: 2.8222795e-05 | W23: -0.0014890627 | X23: 2.8222795e-05
B24: 44476 | C24: =IFERROR(INDEX(Sheet1!F20:F1260,MATCH(Mean_rev!B24,Sheet1!A20:A1260,0)),0) -> 293.65674 | D24: =LN(C24/C23) -> 0.011261669 | G24: =B24 -> 44476 | H24: =IFERROR(INDEX([1]Sheet1!$F$2:$F$1238,MATCH(G24,[1]Sheet1!$A$2:$A$1238,0)),0) -> 17790.35 | I24: =LN(H24/H23) -> 0.0081470247 | P24: X Variable 1 | Q24: 0.99895348 | R24: 0.044390386 | S24: 22.503825 | T24: 3.0267588e-94 | U24: 0.91186451 | V24: 1.0860425 | W24: 0.91186451 | X24: 1.0860425
B25: 44477 | C25: =IFERROR(INDEX(Sheet1!F21:F1261,MATCH(Mean_rev!B25,Sheet1!A21:A1261,0)),0) -> 301.9693 | D25: =LN(C25/C24) -> 0.027913826 | G25: =B25 -> 44477 | H25: =IFERROR(INDEX([1]Sheet1!$F$2:$F$1238,MATCH(G25,[1]Sheet1!$A$2:$A$1238,0)),0) -> 17895.199 | I25: =LN(H25/H24) -> 0.0058763233
B26: 44480 | C26: =IFERROR(INDEX(Sheet1!F22:F1262,MATCH(Mean_rev!B26,Sheet1!A22:A1262,0)),0) -> 298.15555 | D26: =LN(C26/C25) -> -0.012710031 | G26: =B26 -> 44480 | H26: =IFERROR(INDEX([1]Sheet1!$F$2:$F$1238,MATCH(G26,[1]Sheet1!$A$2:$A$1238,0)),0) -> 17945.949 | I26: =LN(H26/H25) -> 0.0028319424
B27: 44481 | C27: =IFERROR(INDEX(Sheet1!F23:F1263,MATCH(Mean_rev!B27,Sheet1!A23:A1263,0)),0) -> 301.03293 | D27: =LN(C27/C26) -> 0.0096043319 | G27: =B27 -> 44481 | H27: =IFERROR(INDEX([1]Sheet1!$F$2:$F$1238,MATCH(G27,[1]Sheet1!$A$2:$A$1238,0)),0) -> 17991.949 | I27: =LN(H27/H26) -> 0.002559973
B28: 44482 | C28: =IFERROR(INDEX(Sheet1!F24:F1264,MATCH(Mean_rev!B28,Sheet1!A24:A1264,0)),0) -> 307.19885 | D28: =LN(C28/C27) -> 0.02027561 | G28: =B28 -> 44482 | H28: =IFERROR(INDEX([1]Sheet1!$F$2:$F$1238,MATCH(G28,[1]Sheet1!$A$2:$A$1238,0)),0) -> 18161.75 | I28: =LN(H28/H27) -> 0.009393342 | P28: RESIDUAL OUTPUT
B29: 44483 | C29: =IFERROR(INDEX(Sheet1!F25:F1265,MATCH(Mean_rev!B29,Sheet1!A25:A1265,0)),0) -> 323.48141 | D29: =LN(C29/C28) -> 0.051646396 | G29: =B29 -> 44483 | H29: =IFERROR(INDEX([1]Sheet1!$F$2:$F$1238,MATCH(G29,[1]Sheet1!$A$2:$A$1238,0)),0) -> 18338.551 | I29: =LN(H29/H28) -> 0.00968771
B30: 44487 | C30: =IFERROR(INDEX(Sheet1!F26:F1266,MATCH(Mean_rev!B30,Sheet1!A26:A1266,0)),0) -> 324.16653 | D30: =LN(C30/C29) -> 0.002115717 | G30: =B30 -> 44487 | H30: =IFERROR(INDEX([1]Sheet1!$F$2:$F$1238,MATCH(G30,[1]Sheet1!$A$2:$A$1238,0)),0) -> 18477.051 | I30: =LN(H30/H29) -> 0.0075240196 | P30: Observation | Q30: Predicted Y | R30: Residuals
B31: 44488 | C31: =IFERROR(INDEX(Sheet1!F27:F1267,MATCH(Mean_rev!B31,Sheet1!A27:A1267,0)),0) -> 324.98862 | D31: =LN(C31/C30) -> 0.002532778 | G31: =B31 -> 44488 | H31: =IFERROR(INDEX([1]Sheet1!$F$2:$F$1238,MATCH(G31,[1]Sheet1!$A$2:$A$1238,0)),0) -> 18418.75 | I31: =LN(H31/H30) -> -0.0031602962 | P31: 1 | Q31: 0.00069023133 | R31: 0.0033270487
B32: 44489 | C32: =IFERROR(INDEX(Sheet1!F28:F1268,MATCH(Mean_rev!B32,Sheet1!A28:A1268,0)),0) -> 320.60403 | D32: =LN(C32/C31) -> -0.013583333 | G32: =B32 -> 44489 | H32: =IFERROR(INDEX([1]Sheet1!$F$2:$F$1238,MATCH(G32,[1]Sheet1!$A$2:$A$1238,0)),0) -> 18266.6 | I32: =LN(H32/H31) -> -0.0082949332 | P32: 2 | Q32: 0.0072527447 | R32: -0.0063622803
B33: 44490 | C33: =IFERROR(INDEX(Sheet1!F29:F1269,MATCH(Mean_rev!B33,Sheet1!A29:A1269,0)),0) -> 318.02347 | D33: =LN(C33/C32) -> -0.0080816452 | G33: =B33 -> 44490 | H33: =IFERROR(INDEX([1]Sheet1!$F$2:$F$1238,MATCH(G33,[1]Sheet1!$A$2:$A$1238,0)),0) -> 18178.1 | I33: =LN(H33/H32) -> -0.0048566829 | P33: 3 | Q33: 0.0055250143 | R33: -0.014765641
B34: 44491 | C34: =IFERROR(INDEX(Sheet1!F30:F1270,MATCH(Mean_rev!B34,Sheet1!A30:A1270,0)),0) -> 311.67484 | D34: =LN(C34/C33) -> -0.020164729 | G34: =B34 -> 44491 | H34: =IFERROR(INDEX([1]Sheet1!$F$2:$F$1238,MATCH(G34,[1]Sheet1!$A$2:$A$1238,0)),0) -> 18114.9 | I34: =LN(H34/H33) -> -0.0034827257 | P34: 4 | Q34: -0.0032466011 | R34: -0.00065416453
B35: 44494 | C35: =IFERROR(INDEX(Sheet1!F31:F1271,MATCH(Mean_rev!B35,Sheet1!A31:A1271,0)),0) -> 304.96091 | D35: =LN(C35/C34) -> -0.021776855 | G35: =B35 -> 44494 | H35: =IFERROR(INDEX([1]Sheet1!$F$2:$F$1238,MATCH(G35,[1]Sheet1!$A$2:$A$1238,0)),0) -> 18125.4 | I35: =LN(H35/H34) -> 0.00057946541 | P35: 5 | Q35: -0.011481923 | R35: 0.0073396873
B36: 44495 | C36: =IFERROR(INDEX(Sheet1!F32:F1272,MATCH(Mean_rev!B36,Sheet1!A32:A1272,0)),0) -> 305.16641 | D36: =LN(C36/C35) -> 0.00067364752 | G36: =B36 -> 44495 | H36: =IFERROR(INDEX([1]Sheet1!$F$2:$F$1238,MATCH(G36,[1]Sheet1!$A$2:$A$1238,0)),0) -> 18268.4 | I36: =LN(H36/H35) -> 0.0078585217 | P36: 6 | Q36: 0.0087051203 | R36: -0.001036669
B37: 44496 | C37: =IFERROR(INDEX(Sheet1!F33:F1273,MATCH(Mean_rev!B37,Sheet1!A33:A1273,0)),0) -> 306.51379 | D37: =LN(C37/C36) -> 0.004405517 | G37: =B37 -> 44496 | H37: =IFERROR(INDEX([1]Sheet1!$F$2:$F$1238,MATCH(G37,[1]Sheet1!$A$2:$A$1238,0)),0) -> 18210.949 | I37: =LN(H37/H36) -> -0.0031497941 | P37: 7 | Q37: -0.001603911 | R37: 0.0024275754
B38: 44497 | C38: =IFERROR(INDEX(Sheet1!F34:F1274,MATCH(Mean_rev!B38,Sheet1!A34:A1274,0)),0) -> 300.02814 | D38: =LN(C38/C37) -> -0.021386498 | G38: =B38 -> 44497 | H38: =IFERROR(INDEX([1]Sheet1!$F$2:$F$1238,MATCH(G38,[1]Sheet1!$A$2:$A$1238,0)),0) -> 17857.25 | I38: =LN(H38/H37) -> -0.01961343 | P38: 8 | Q38: 0.014877068 | R38: -0.0057147871
B39: 44498 | C39: =IFERROR(INDEX(Sheet1!F35:F1275,MATCH(Mean_rev!B39,Sheet1!A35:A1275,0)),0) -> 295.39233 | D39: =LN(C39/C38) -> -0.015571842 | G39: =B39 -> 44498 | H39: =IFERROR(INDEX([1]Sheet1!$F$2:$F$1238,MATCH(G39,[1]Sheet1!$A$2:$A$1238,0)),0) -> 17671.65 | I39: =LN(H39/H38) -> -0.010447906 | P39: 9 | Q39: 0.00096361662 | R39: 0.0022937426
B40: 44501 | C40: =IFERROR(INDEX(Sheet1!F36:F1276,MATCH(Mean_rev!B40,Sheet1!A36:A1276,0)),0) -> 299.36588 | D40: =LN(C40/C39) -> 0.01336207 | G40: =B40 -> 44501 | H40: =IFERROR(INDEX([1]Sheet1!$F$2:$F$1238,MATCH(G40,[1]Sheet1!$A$2:$A$1238,0)),0) -> 17929.65 | I40: =LN(H40/H39) -> 0.014494106 | P40: 10 | Q40: -0.00062409162 | R40: -0.033353924
B41: 44502 | C41: =IFERROR(INDEX(Sheet1!F37:F1277,MATCH(Mean_rev!B41,Sheet1!A37:A1277,0)),0) -> 298.61227 | D41: =LN(C41/C40) -> -0.0025204984 | G41: =B41 -> 44502 | H41: =IFERROR(INDEX([1]Sheet1!$F$2:$F$1238,MATCH(G41,[1]Sheet1!$A$2:$A$1238,0)),0) -> 17888.949 | I41: =LN(H41/H40) -> -0.0022726287 | P41: 11 | Q41: -0.0067067014 | R41: -0.015404731
B42: 44503 | C42: =IFERROR(INDEX(Sheet1!F38:F1278,MATCH(Mean_rev!B42,Sheet1!A38:A1278,0)),0) -> 298.01852 | D42: =LN(C42/C41) -> -0.0019903438 | G42: =B42 -> 44503 | H42: =IFERROR(INDEX([1]Sheet1!$F$2:$F$1238,MATCH(G42,[1]Sheet1!$A$2:$A$1238,0)),0) -> 17829.199 | I42: =LN(H42/H41) -> -0.0033456413 | P42: 12 | Q42: -0.0028319379 | R42: 0.004628304
... B1242: 46276 | C1242: =IFERROR(INDEX(Sheet1!F1238:F2478,MATCH(Mean_rev!B1242,Sheet1!A1238:A2478,0)),0) -> 167.39999 | D1242: =LN(C1242/C1241) -> 0.006592717 | G1242: =B1242 -> 46276 | H1242: =IFERROR(INDEX([1]Sheet1!$F$2:$F$1238,MATCH(G1242,[1]Sheet1!$A$2:$A$1238,0)),0) -> 23398.1 | I1242: =LN(H1242/H1241) -> -0.0034005213 | P1242: 1212 | Q1242: -0.00019591581 | R1242: -0.010688028
...
